<?xml version="1.0" encoding="UTF-8"?>
<testsuite name="Create Patient and verify patient is created "
           tests="3"
           failures="1"
           errors="0"
           skipped="0"
           time="21.633">
    <properties></properties>

            <testcase
                name="createPatient"
                time="8.187"
                classname="chl.CreatePatient">

            <failure type="java.lang.AssertionError" message="The following asserts failed:
	Same email id did not expect [Email ID already exist.] but found [Email ID already exist.]">
                <![CDATA[java.lang.AssertionError: The following asserts failed:
	Same email id did not expect [Email ID already exist.] but found [Email ID already exist.]
                org.testng.asserts.SoftAssert.assertAll(SoftAssert.java:46)org.testng.asserts.SoftAssert.assertAll(SoftAssert.java:30)chl.CreatePatient.createPatient(CreatePatient.java:142)java.base/jdk.internal.reflect.NativeMethodAccessorImpl.invoke0(Native Method)java.base/jdk.internal.reflect.NativeMethodAccessorImpl.invoke(NativeMethodAccessorImpl.java:77)java.base/jdk.internal.reflect.DelegatingMethodAccessorImpl.invoke(DelegatingMethodAccessorImpl.java:43)java.base/java.lang.reflect.Method.invoke(Method.java:568)org.testng.internal.invokers.MethodInvocationHelper.invokeMethod(MethodInvocationHelper.java:139)org.testng.internal.invokers.TestInvoker.invokeMethod(TestInvoker.java:677)org.testng.internal.invokers.TestInvoker.invokeTestMethod(TestInvoker.java:221)org.testng.internal.invokers.MethodRunner.runInSequence(MethodRunner.java:50)org.testng.internal.invokers.TestInvoker$MethodInvocationAgent.invoke(TestInvoker.java:962)org.testng.internal.invokers.TestInvoker.invokeTestMethods(TestInvoker.java:194)org.testng.internal.invokers.TestMethodWorker.invokeTestMethods(TestMethodWorker.java:148)org.testng.internal.invokers.TestMethodWorker.run(TestMethodWorker.java:128)java.base/java.util.ArrayList.forEach(ArrayList.java:1511)org.testng.TestRunner.privateRun(TestRunner.java:806)org.testng.TestRunner.run(TestRunner.java:601)org.testng.SuiteRunner.runTest(SuiteRunner.java:433)org.testng.SuiteRunner.runSequentially(SuiteRunner.java:427)org.testng.SuiteRunner.privateRun(SuiteRunner.java:387)org.testng.SuiteRunner.run(SuiteRunner.java:330)org.testng.SuiteRunnerWorker.runSuite(SuiteRunnerWorker.java:52)org.testng.SuiteRunnerWorker.run(SuiteRunnerWorker.java:95)org.testng.TestNG.runSuitesSequentially(TestNG.java:1256)org.testng.TestNG.runSuitesLocally(TestNG.java:1176)org.testng.TestNG.runSuites(TestNG.java:1099)org.testng.TestNG.run(TestNG.java:1067)org.testng.remote.AbstractRemoteTestNG.run(AbstractRemoteTestNG.java:115)org.testng.remote.RemoteTestNG.initAndRun(RemoteTestNG.java:251)org.testng.remote.RemoteTestNG.main(RemoteTestNG.java:77)
]]>
            </failure>
    </testcase>


            <testcase
                name="login"
                time="8.289"
                classname="chl.CreatePatient">
            </testcase>
            <testcase
                name="patientList"
                time="5.157"
                classname="chl.CreatePatient">
            </testcase>
</testsuite>
